in development. ' + 'See https://reactjs.org/link/crossorigin-error for more information.');
        }

        this.onError(error);
      } // Remove our event listeners


      window.removeEventListener('error', handleWindowError);

      if (!didCall) {
        // Something went really wrong, and our event was not dispatched.
        // https://github.com/facebook/react/issues/16734
        // https://github.com/facebook/react/issues/16585
        // Fall back to the production implementation.
        restoreAfterDispatch();
        return invokeGuardedCallbackProd.apply(this, arguments);
      }
    };
  }
}

var invokeGuardedCallbackImpl$1 = invokeGuardedCallbackImpl;

var hasError = false;
var caughtError = null; // Used by event system to capture/rethrow the first error.

var hasRethrowError = false;
var rethrowError = null;
var reporter = {
  onError: function (error) {
    hasError = true;
    caughtError = error;
  }
};
/**
 * Call a function while guarding against errors that happens within it.
 * Returns an error if it throws, otherwise null.
 *
 * In production, this is implemented using a try-catch. The reason we don't
 * use a try-catch directly is so that we can swap out a different
 * implementation in DEV mode.
 *
 * @param {String} name of the guard to use for logging or debugging
 * @param {Function} func The function to invoke
 * @param {*} context The context to use when calling the function
 * @param {...*} args Arguments for function
 */

function invokeGuardedCallback(name, func, context, a, b, c, d, e, f) {
  hasError = false;
  caughtError = null;
  invokeGuardedCallbackImpl$1.apply(reporter, arguments);
}
/**
 * Same as invokeGuardedCallback, but instead of returning an error, it stores
 * it in a global so it can be rethrown by `rethrowCaugh